File: tensile-test-analysis/Clean_Measurements.csv
,Specimen ID,AvgThickness,AvgWidth,CrsArea,InitGauge,Yield Stress (MPA),Yield Strain (%),Max Strain (%),Material,Orientation
0,1,3.25,13.48,43.79,68.3,51.62241173783969,2.0357811961932653,3.991701592972182,PLA,Vertical
1,2,3.35,13.49,45.18,65.88,49.00726412129261,2.001941964177292,4.4822117455980575,PLA,Vertical
2,3,3.25,13.5,43.88,66.5,50.1236281905196,1.9878249413533835,3.5408339112781952,PLA,Vertical
3,4,3.35,13.56,45.43,63.29,49.11558003521902,2.05077253278559,4.604983092115658,PLA,Vertical
4,6,3.38,13.05,44.15,67.31,37.26924702151755,2.44305031496063,3.5709609359679098,PLA,Horizontal
5,7,3.25,13.08,42.49,67.88,38.66585335373029,2.2136720757218624,3.1471199749558045,PLA,Horizontal
6,8,3.27,13.03,42.55,62.95,37.74744843713279,2.325788956314536,4.356634247815727,PLA,Horizontal
7,9,3.25,13.1,42.58,63.7,38.03649586660404,2.319474422291994,5.229214483516484,PLA,Horizontal
8,11,3.27,13.48,44.02,61.36,42.25780829168559,4.022244212842243,36.27742596153846,PETG,Vertical
9,12,3.35,13.48,45.14,64.74,42.25839758529021,3.999486027185666,5.721003691689837,PETG,Vertical
10,13,3.3,13.48,44.47,62.16,43.54093503485496,3.991309586550837,5.374524737773488,PETG,Vertical
11,14,3.3,13.5,44.55,60.68,42.77480754208754,3.934652300593276,5.06698063612393,PETG,Vertical
12,16,3.22,13.01,41.86,64.89,32.15686636407072,3.976085222684543,7.891362502696872,PETG,Horizontal
13,17,3.32,13.1,43.45,62.65,32.68874121979287,4.046715647246608,8.181222609736633,PETG,Horizontal
14,18,3.22,13.08,42.06,65.68,32.64448644793153,3.9873438246041406,5.991151795066991,PETG,Horizontal
15,19,3.25,13.13,42.66,64.04,33.24578952180028,4.119993671143035,8.290184803247968,PETG,Horizontal
16,21,3.27,13.15,42.96,65.26,32.297272928305404,4.059310855041373,8.494849589334967,PETG,Horizontal