File: tensile-test-analysis/Clean_TensileTest.csv
,Specimen,Elongation (mm),Force (N),Material,Orientation,Stress (MPA),Strain (%)
0,Speci1Force,0.0,0.6811414361,PLA,Vertical,0.015554725647408084,0.0
1,Speci1Force,-1.439452171e-05,0.4388929009,PLA,Vertical,0.01002267414706554,-2.1075434421669106e-05
5,Speci1Force,-3.718445078e-05,0.6826730371,PLA,Vertical,0.015589701692167163,-5.444282691068815e-05
9,Speci1Force,-9.300652891e-06,3.838648319,PLA,Vertical,0.0876603863667504,-1.3617354159590042e-05
13,Speci1Force,0.0009464961477,7.989069462,PLA,Vertical,0.1824404992464033,0.0013857923099560763
17,Speci1Force,0.002101690043,12.357234,PLA,Vertical,0.2821930577757479,0.003077145011713031
21,Speci1Force,0.003605721984,16.41817665,PLA,Vertical,0.3749298161680749,0.005279241557833089
25,Speci1Force,0.004969627131,20.01723671,PLA,Vertical,0.45711890180406484,0.007276174423133236
29,Speci1Force,0.006529637147,22.01915932,PLA,Vertical,0.5028353350079927,0.009560230083455344
33,Speci1Force,0.006522647105,23.98900795,PLA,Vertical,0.5478193183375201,0.009549995761347
37,Speci1Force,0.007447226904,26.95787239,PLA,Vertical,0.6156170904316054,0.010903699713030747
41,Speci1Force,0.008156972937,30.81833076,PLA,Vertical,0.7037755368805663,0.011942859351390923
45,Speci1Force,0.0096915178,35.07034683,PLA,Vertical,0.8008756983329527,0.01418963074670571
49,Speci1Force,0.01189815067,38.88017273,PLA,Vertical,0.887877888330669,0.017420425578330893
53,Speci1Force,0.0134222582,42.88243103,PLA,Vertical,0.9792745154144782,0.019651915373352858
57,Speci1Force,0.01519683748,46.7776947,PLA,Vertical,1.0682277848823931,0.022250128081991213
61,Speci1Force,0.01750385016,51.03447342,PLA,Vertical,1.1654367074674583,0.02562789188872621
65,Speci1Force,0.01978563331,55.08238602,PLA,Vertical,1.257875908198219,0.028968716412884333
69,Speci1Force,0.02217744663,59.43297195,PLA,Vertical,1.3572270369947477,0.03247063928257687
73,Speci1Force,0.02517366782,63.67638016,PLA,Vertical,1.454130627083809,0.036857493147877014
77,Speci1Force,0.02754778974,67.8839035,PLA,Vertical,1.550214740808404,0.04033351352855051
81,Speci1Force,0.02979860269,72.16765594,PLA,Vertical,1.6480396423841062,0.043628993689604684
85,Speci1Force,0.03272231668,76.87419891,PLA,Vertical,1.7555195001141815,0.04790968767203515
89,Speci1Force,0.03463351727,81.62200165,PLA,Vertical,1.8639415768440284,0.05070793158125915
93,Speci1Force,0.03714473546,85.94841766,PLA,Vertical,1.9627407549668876,0.054384678565153735
97,Speci1Force,0.039369151,90.37792206,PLA,Vertical,2.063894086777803,0.05764150951683748
101,Speci1Force,0.04222245142,94.69676971,PLA,Vertical,2.162520431833752,0.06181910896046852
105,Speci1Force,0.0440034233,99.07518768,PLA,Vertical,2.2625071404430237,0.06442668125915081
109,Speci1Force,0.0465815179,103.6423264,PLA,Vertical,2.3668035259191598,0.0682013439238653
113,Speci1Force,0.04856216535,108.0488205,PLA,Vertical,2.4674313884448504,0.07110126698389459
117,Speci1Force,0.0505457446,112.4792404,PLA,Vertical,2.5686056268554465,0.07400548257686676
121,Speci1Force,0.05322541296,116.8383484,PLA,Vertical,2.668151367892213,0.07792886231332358
125,Speci1Force,0.05506888777,121.1642761,PLA,Vertical,2.7669393948390044,0.080627946954612
129,Speci1Force,0.05798974633,125.6654968,PLA,Vertical,2.869730459008906,0.08490446021961932
133,Speci1Force,0.05979123712,130.0785828,PLA,Vertical,2.9705088559031743,0.08754207484626648
137,Speci1Force,0.0624675341,134.4025574,PLA,Vertical,3.0692522813427727,0.09146051844802343
141,Speci1Force,0.06489352882,138.6271667,PLA,Vertical,3.165726574560402,0.09501248729136165
145,Speci1Force,0.06783743948,143.1823425,PLA,Vertical,3.2697497716373602,0.09932275180087848
149,Speci1Force,0.07005714625,147.5417175,PLA,Vertical,3.369301609956611,0.10257268850658859
153,Speci1Force,0.07140544057,152.1686707,PLA,Vertical,3.4749639346882852,0.10454676510980966
157,Speci1Force,0.07255236059,157.0119324,PLA,Vertical,3.585565937428637,0.10622600379209372
161,Speci1Force,0.07465364784,161.4611511,PLA,Vertical,3.6871694701986755,0.10930255906295755
165,Speci1Force,0.07803346962,165.6430359,PLA,Vertical,3.7826680954555836,0.11425105361639826
169,Speci1Force,0.08149452507,169.9555359,PLA,Vertical,3.881149483900434,0.11931848472913617
173,Speci1Force,0.08391048014,174.3920593,PLA,Vertical,3.982463103448276,0.12285575423133235
177,Speci1Force,0.08615202457,178.6451111,PLA,Vertical,4.079586917104362,0.12613766408491947
181,Speci1Force,0.08856471628,183.0474548,PLA,Vertical,4.18012,0.12967015560761347
185,Speci1Force,0.09019523114,187.3687439,PLA,Vertical,4.27880209865266,0.13205743944363105
189,Speci1Force,0.09142757952,191.995697,PLA,Vertical,4.384464421100708,0.13386175625183017
193,Speci1Force,0.09300720692,196.5640564,PLA,Vertical,4.488788682347568,0.1361745342898975
197,Speci1Force,0.09524166584,201.080658,PLA,Vertical,4.591930988810231,0.13944607004392387
201,Speci1Force,0.09755718708,205.4761658,PLA,Vertical,4.692307965288879,0.14283629147877014
205,Speci1Force,0.1001359224,210.2242126,PLA,Vertical,4.800735615437314,0.14661189224011711
209,Speci1Force,0.1026564837,214.5230408,PLA,Vertical,4.898904791048184,0.1503023187408492
213,Speci1Force,0.106145978,218.995697,PLA,Vertical,5.0010435487554235,0.1554113879941435
217,Speci1Force,0.1078877971,223.5992126,PLA,Vertical,5.10617064626627,0.1579616355783309
221,Speci1Force,0.110043101,227.8755798,PLA,Vertical,5.203826896551724,0.16111727818448027
225,Speci1Force,0.112315245,232.9405975,PLA,Vertical,5.319492977848824,0.1644439897510981
229,Speci1Force,0.1137458384,237.4093475,PLA,Vertical,5.421542532541676,0.1665385628111274
233,Speci1Force,0.1168443263,242.017746,PLA,Vertical,5.526781137245947,0.17107514831625184
237,Speci1Force,0.1192342341,246.8507538,PLA,Vertical,5.637148979219,0.1745742812591508
241,Speci1Force,0.1218263209,251.5157928,PLA,Vertical,5.743681041333638,0.17836943030746708
245,Speci1Force,0.1232908294,255.9659882,PLA,Vertical,5.845306878282713,0.18051365944363104
249,Speci1Force,0.1248870715,260.553894,PLA,Vertical,5.950077506279973,0.1828507635431918
253,Speci1Force,0.1264795661,265.1261597,PLA,Vertical,6.054490972824846,0.18518238081991217
257,Speci1Force,0.1285056472,269.7902222,PLA,Vertical,6.1610007353277005,0.18814882459736457
261,Speci1Force,0.131563127,274.0421753,PLA,Vertical,6.258099458780544,0.19262536896046853
265,Speci1Force,0.1346330047,279.116394,PLA,Vertical,6.37397565654259,0.1971200654465593
269,Speci1Force,0.137662828,283.7824097,PLA,Vertical,6.480530022836264,0.20155611713030744
273,Speci1Force,0.1390539706,288.0910034,PLA,Vertical,6.578922205983101,0.20359292913616397
277,Speci1Force,0.1415645182,292.8253784,PLA,Vertical,6.687037643297556,0.20726869428989747
281,Speci1Force,0.1439010203,297.2814331,PLA,Vertical,6.788797284768212,0.2106896344070278
285,Speci1Force,0.1462232172,302.2384644,PLA,Vertical,6.901997360127883,0.21408962986822844
289,Speci1Force,0.1482698023,306.7091675,PLA,Vertical,7.004091516327929,0.21708609414348465
293,Speci1Force,0.1503793299,311.3751831,PLA,Vertical,7.1106458803379775,0.22017471434846264
297,Speci1Force,0.1524392664,316.451355,PLA,Vertical,7.2265666818908425,0.22319072679355784
301,Speci1Force,0.1548363268,321.6447144,PLA,Vertical,7.3451636081297105,0.2267003320644217
305,Speci1Force,0.156845808,326.4142456,PLA,Vertical,7.454081881708153,0.22964247144948757
309,Speci1Force,0.1600472927,331.3322144,PLA,Vertical,7.566389915505823,0.2343298575402636
313,Speci1Force,0.1623344421,336.62323,PLA,Vertical,7.687216944507878,0.23767853894582727
317,Speci1Force,0.1644039154,341.3009644,PLA,Vertical,7.7940389221283395,0.24070851449487554
321,Speci1Force,0.1663732529,345.90448,PLA,Vertical,7.899166019639186,0.24359187833089313
325,Speci1Force,0.1692085266,350.6339722,PLA,Vertical,8.007169952043846,0.24774308433382136
329,Speci1Force,0.1712713242,355.7706909,PLA,Vertical,8.124473416305092,0.2507632857979502
333,Speci1Force,0.1734666824,360.5675659,PLA,Vertical,8.234016120118747,0.25397757306002927
337,Speci1Force,0.1752939224,365.4894409,PLA,Vertical,8.346413356930805,0.2566528878477306
341,Speci1Force,0.1782169342,370.0460815,PLA,Vertical,8.450470004567253,0.2609325537335286
345,Speci1Force,0.1808443069,374.5783081,PLA,Vertical,8.553969127654716,0.264779365885798
349,Speci1Force,0.1837859154,379.6046753,PLA,Vertical,8.668752575930577,0.2690862597364568
353,Speci1Force,0.1857819557,384.09198,PLA,Vertical,8.771225850650833,0.2720087199121523
357,Speci1Force,0.1882185936,389.0724487,PLA,Vertical,8.884961148664079,0.27557627174231336
361,Speci1Force,0.1900410652,394.3849487,PLA,Vertical,9.00627880109614,0.2782446049780381
365,Speci1Force,0.1928210258,399.2677612,PLA,Vertical,9.117783996346198,0.28231482547584186
369,Speci1Force,0.1950343549,403.8116455,PLA,Vertical,9.221549337748344,0.2855554244509517
373,Speci1Force,0.1974690855,408.1964111,PLA,Vertical,9.321681002511989,0.28912018374816983
377,Speci1Force,0.1996053159,412.819458,PLA,Vertical,9.42725412194565,0.29224790029282577
381,Speci1Force,0.2013772428,417.1905518,PLA,Vertical,9.527073573875313,0.2948422295754026
385,Speci1Force,0.2039216459,422.2628174,PLA,Vertical,9.642905170130167,0.2985675635431918
389,Speci1Force,0.2059620321,426.9346924,PLA,Vertical,9.749593340945422,0.30155495183016107
393,Speci1Force,0.208196491,431.8624268,PLA,Vertical,9.862124384562685,0.3048264875549049
397,Speci1Force,0.2107218206,436.5635986,PLA,Vertical,9.96948158483672,0.30852389546120057
401,Speci1Force,0.2134188116,441.6827393,PLA,Vertical,10.0863836332496,0.31247263777452416
405,Speci1Force,0.2163246572,446.7667236,PLA,Vertical,10.20248284083124,0.3167271701317716
409,Speci1Force,0.2183388174,451.1104736,PLA,Vertical,10.30167786252569,0.3196761601756955
413,Speci1Force,0.2214306295,455.9093018,PLA,Vertical,10.411265170130166,0.32420297144948756
417,Speci1Force,0.223695606,460.5167236,PLA,Vertical,10.5164814706554,0.32751918887262077
421,Speci1Force,0.2262452543,465.0147705,PLA,Vertical,10.61920005709066,0.33125220248901904
425,Speci1Force,0.2288402021,470.381958,PLA,Vertical,10.741766567709522,0.33505154040995605
429,Speci1Force,0.2315495908,475.491333,PLA,Vertical,10.858445604019183,0.3390184345534407
433,Speci1Force,0.2334655225,480.0733643,PLA,Vertical,10.963082080383648,0.34182360541727674
437,Speci1Force,0.2359488904,484.7608643,PLA,Vertical,11.070127067823703,0.34545957598828697
441,Speci1Force,0.2380269468,489.6749268,PLA,Vertical,11.182345896323362,0.34850211830161054
445,Speci1Force,0.2400258482,494.9425049,PLA,Vertical,11.302637700388217,0.35142876749633967
449,Speci1Force,0.2427533567,499.8448486,PLA,Vertical,11.414588915277461,0.3554221913616398
453,Speci1Force,0.2454026639,504.772583,PLA,Vertical,11.527119958894724,0.3593011184480235
457,Speci1Force,0.2475036085,509.6260986,PLA,Vertical,11.637956122402375,0.3623771720351391
461,Speci1Force,0.2499040067,514.9464111,PLA,Vertical,11.759452183146838,0.3658916642752562
465,Speci1Force,0.2527097166,519.9815674,PLA,Vertical,11.87443634163051,0.36999958506588587
469,Speci1Force,0.254594177,524.9620361,PLA,Vertical,11.988171639643754,0.37275867789165446
473,Speci1Force,0.2566922605,529.7969971,PLA,Vertical,12.098584085407628,0.37583054245973646
477,Speci1Force,0.2591994703,534.3282471,PLA,Vertical,12.20206090659968,0.3795014206442167
481,Speci1Force,0.2612985075,539.0968018,PLA,Vertical,12.310956880566339,0.3825746815519766
485,Speci1Force,0.2646668851,543.9815674,PLA,Vertical,12.422506677323591,0.387506420351391
489,Speci1Force,0.2674020231,549.4678955,PLA,Vertical,12.54779391413565,0.3915110147877013
493,Speci1Force,0.2698138654,554.4718018,PLA,Vertical,12.662064439369718,0.3950422626647145
497,Speci1Force,0.2726958692,559.1651611,PLA,Vertical,12.769243231331354,0.3992618875549048
501,Speci1Force,0.2746852338,563.4796143,PLA,Vertical,12.867769223567024,0.4021745736456808
505,Speci1Force,0.2774032056,568.4718018,PLA,Vertical,12.981772135190683,0.40615403455344073
509,Speci1Force,0.2801822126,573.381958,PLA,Vertical,13.09390175839233,0.41022285885797943
513,Speci1Force,0.2828410566,579.1964111,PLA,Vertical,13.226682144325189,0.4141157490483162
517,Speci1Force,0.2846396863,584.319458,PLA,Vertical,13.343673395752456,0.4167491746705711
521,Speci1Force,0.2869428098,589.4854736,PLA,Vertical,13.461645891756108,0.4201212442166911
525,Speci1Force,0.2890466154,594.3292236,PLA,Vertical,13.572259045444165,0.4232014866764275
529,Speci1Force,0.2916377485,599.3897705,PLA,Vertical,13.687823030372233,0.4269952393850659
533,Speci1Force,0.2943728566,604.2470093,PLA,Vertical,13.798744217857957,0.4309997900439239
537,Speci1Force,0.2970870137,608.8759155,PLA,Vertical,13.9044511418132,0.4349736657393851
541,Speci1Force,0.2995150685,613.8231812,PLA,Vertical,14.017428207353278,0.43852865080527087
545,Speci1Force,0.3018048406,618.4091187,PLA,Vertical,14.122153886732132,0.44188117218155204
549,Speci1Force,0.3044179082,623.2040405,PLA,Vertical,14.231651986754967,0.4457070398243045
553,Speci1Force,0.3062947392,628.2665405,PLA,Vertical,14.347260573190226,0.4484549622254759
557,Speci1Force,0.3087123036,633.3348999,PLA,Vertical,14.463002966430691,0.4519945879941435
561,Speci1Force,0.3111928105,638.6630249,PLA,Vertical,14.584677435487555,0.45562636969253306
565,Speci1Force,0.3136361241,643.180603,PLA,Vertical,14.687842041562002,0.45920369560761354
569,Speci1Force,0.3163073659,648.1395874,PLA,Vertical,14.801086718428865,0.46311473777452417
573,Speci1Force,0.3189023137,652.7626343,PLA,Vertical,14.906659837862525,0.46691407569546123
577,Speci1Force,0.3212969899,658.336853,PLA,Vertical,15.033954167618178,0.47042019019033676
581,Speci1Force,0.3241742253,663.2470093,PLA,Vertical,15.146083793103447,0.4746328335285505
585,Speci1Force,0.3274701238,668.3954468,PLA,Vertical,15.263654870975108,0.47945845358711564
589,Speci1Force,0.330745995,673.5575562,PLA,Vertical,15.381538163964375,0.4842547510980967
593,Speci1Force,0.3325832486,678.8251343,PLA,Vertical,15.501829968029229,0.48694472708638364
597,Speci1Force,0.3351219296,683.633728,PLA,Vertical,15.611640283169674,0.4906616831625183
601,Speci1Force,0.3367906213,689.3778687,PLA,Vertical,15.74281499657456,0.49310486281112736
605,Speci1Force,0.3392520547,693.9813843,PLA,Vertical,15.847942094085406,0.4967087184480235
609,Speci1Force,0.3419528604,698.9266968,PLA,Vertical,15.960874555834664,0.5006630459736457
613,Speci1Force,0.3459401727,704.4286499,PLA,Vertical,16.086518609271522,0.5065009849194729
617,Speci1Force,0.3491578698,710.0946655,PLA,Vertical,16.215909237268782,0.5112121080527087
621,Speci1Force,0.3510375619,714.5575562,PLA,Vertical,16.317824987440055,0.5139642194729136
625,Speci1Force,0.3531890512,719.5282593,PLA,Vertical,16.431337275633705,0.5171142770131771
629,Speci1Force,0.3557935357,724.5829468,PLA,Vertical,16.546767453756566,0.5209275778916546
633,Speci1Force,0.358492434,729.9872437,PLA,Vertical,16.670181404430235,0.524879112737921
637,Speci1Force,0.3607259393,734.9032593,PLA,Vertical,16.782444834437086,0.5281492522693998
641,Speci1Force,0.3627753854,739.6630249,PLA,Vertical,16.891140098195937,0.5311499054172767
645,Speci1Force,0.3654332757,744.9598999,PLA,Vertical,17.012100934003197,0.5350413992679356
649,Speci1Force,0.3681502938,750.0985718,PLA,Vertical,17.129449002055264,0.5390194638360175
653,Speci1Force,0.3707957864,755.1845093,PLA,Vertical,17.245592813427724,0.5428928058565154
657,Speci1Force,0.3729692101,760.1356812,PLA,Vertical,17.35865908198219,0.5460749781844803
661,Speci1Force,0.3756909966,764.9891968,PLA,Vertical,17.46949524548984,0.5500600243045388
665,Speci1Force,0.3788190484,770.4559937,PLA,Vertical,17.59433646266271,0.5546398951683749
669,Speci1Force,0.3820357919,775.3876343,PLA,Vertical,17.70695670929436,0.5593496221083455
673,Speci1Force,0.3847108483,780.0829468,PLA,Vertical,17.814180105046812,0.563266249341142
677,Speci1Force,0.3872190118,785.414978,PLA,Vertical,17.935943777118066,0.5669385238653002
681,Speci1Force,0.3893409371,789.8270874,PLA,Vertical,18.036699872116923,0.5700452959004393
685,Speci1Force,0.3911214471,794.6532593,PLA,Vertical,18.146911607672983,0.5726521919472914
689,Speci1Force,0.3943353295,800.0145874,PLA,Vertical,18.26934431148664,0.5773577298682284
693,Speci1Force,0.3969464898,804.9286499,PLA,Vertical,18.381563139986298,0.5811808049780381
697,Speci1Force,0.3992267251,809.6317749,PLA,Vertical,18.488964944051155,0.5845193632503661
701,Speci1Force,0.4017501473,815.3817749,PLA,Vertical,18.62027346197762,0.588213978477306
705,Speci1Force,0.403966248,820.8140869,PLA,Vertical,18.74432717287052,0.5914586354319181
709,Speci1Force,0.4060667157,826.2359619,PLA,Vertical,18.868142541676182,0.5945339907759883
713,Speci1Force,0.4086073041,831.3179932,PLA,Vertical,18.984197150034255,0.5982537395314789
717,Speci1Force,0.4109867215,836.3453369,PLA,Vertical,19.0990028979219,0.6017375131771595
721,Speci1Force,0.4140632749,840.9976807,PLA,Vertical,19.205245049097968,0.6062419837481698
725,Speci1Force,0.4178913236,846.1539307,PLA,Vertical,19.322994535282028,0.6118467402635431
729,Speci1Force,0.4202468991,850.9332275,PLA,Vertical,19.432135818680067,0.6152956062957541
733,Speci1Force,0.4237821698,855.7203369,PLA,Vertical,19.541455512674126,0.6204716980966325
737,Speci1Force,0.4261234403,860.612915,PLA,Vertical,19.65318371774378,0.6238996197657394
741,Speci1Force,0.4284361005,865.3863525,PLA,Vertical,19.762191196620233,0.6272856522693997
745,Speci1Force,0.4301164746,870.2418213,PLA,Vertical,19.873071963918704,0.6297459364568082
749,Speci1Force,0.4334543347,875.4683838,PLA,Vertical,19.992427124914364,0.634632993704246
753,Speci1Force,0.4357717633,880.6734619,PLA,Vertical,20.111291662480017,0.6380260077598829
757,Speci1Force,0.4389455914,885.7281494,PLA,Vertical,20.226721840602877,0.6426729010248903
761,Speci1Force,0.4413908124,890.987915,PLA,Vertical,20.346835236355332,0.6462530196193265
765,Speci1Force,0.4437578321,895.9801025,PLA,Vertical,20.460838147978993,0.6497186414348463
769,Speci1Force,0.4462555051,901.3355713,PLA,Vertical,20.583137047271066,0.6533755565153734
773,Speci1Force,0.4495390058,906.8101807,PLA,Vertical,20.70815667275634,0.6581830245973647
777,Speci1Force,0.4513795972,911.47229,PLA,Vertical,20.814621831468372,0.6608778875549048
781,Speci1Force,0.4545362592,916.5738525,PLA,Vertical,20.931122459465634,0.6654996474377746
785,Speci1Force,0.4567268491,921.5582275,PLA,Vertical,21.04494696277689,0.66870695329429
789,Speci1Force,0.4598005414,926.7125244,PLA,Vertical,21.162651847453755,0.6732072348462664
793,Speci1Force,0.4625557065,931.9625244,PLA,Vertical,21.282542233386618,0.6772411515373353
797,Speci1Force,0.4658783078,937.081665,PLA,Vertical,21.399444279515873,0.6821058679355784
801,Speci1Force,0.4686134458,942.6109619,PLA,Vertical,21.525712763187943,0.6861104623718887
805,Speci1Force,0.470598042,946.97229,PLA,Vertical,21.62530920301439,0.6890161669106881
809,Speci1Force,0.4726551175,951.8590088,PLA,Vertical,21.736903603562457,0.6920279904831625
813,Speci1Force,0.4760807157,956.9273682,PLA,Vertical,21.852645996802924,0.69704350761347
817,Speci1Force,0.4787023664,962.0758057,PLA,Vertical,21.970217074674586,0.7008819420204979
821,Speci1Force,0.4810550809,966.75354,PLA,Vertical,22.077039050011418,0.7043266191800879
825,Speci1Force,0.4842031598,971.4664307,PLA,Vertical,22.184663866179495,0.7089358122986823
829,Speci1Force,0.4856956601,976.050415,PLA,Vertical,22.289344941767528,0.7111210250366032
833,Speci1Force,0.4895237088,981.4215088,PLA,Vertical,22.412000657684402,0.7167257815519766
837,Speci1Force,0.4915869832,986.6988525,PLA,Vertical,22.532515471568853,0.7197466811127379
841,Speci1Force,0.4948189855,991.7008057,PLA,Vertical,22.64674139529573,0.7244787489019033
845,Speci1Force,0.4964001775,996.6558838,PLA,Vertical,22.75989686686458,0.726793817715959
849,Speci1Force,0.4998734593,1001.913696,PLA,Vertical,22.879965654258964,0.7318791497803807
853,Speci1Force,0.5018456578,1006.767212,PLA,Vertical,22.99080182690112,0.7347667024890191
857,Speci1Force,0.5055554509,1011.062134,PLA,Vertical,23.088881799497603,0.7401983175695461
861,Speci1Force,0.5078652501,1016.282837,PLA,Vertical,23.20810315140443,0.7435801612005858
865,Speci1Force,0.5114853978,1021.984009,PLA,Vertical,23.33829662023293,0.7488805238653002
869,Speci1Force,0.5133746266,1026.890259,PLA,Vertical,23.450337040420187,0.7516465982430454
873,Speci1Force,0.515502274,1031.204712,PLA,Vertical,23.548863028088604,0.754761748169839
877,Speci1Force,0.5186493993,1036.669556,PLA,Vertical,23.673659648321536,0.7593695450951684
881,Speci1Force,0.5207751393,1042.261353,PLA,Vertical,23.801355400776437,0.7624819023426062
885,Speci1Force,0.5244410634,1047.704712,PLA,Vertical,23.925661383877596,0.7678492875549049
889,Speci1Force,0.5257321,1052.071655,PLA,Vertical,24.025386047042705,0.7697395314787702
893,Speci1Force,0.5284596086,1057.001343,PLA,Vertical,24.13796170358529,0.7737329554904832
897,Speci1Force,0.5312471986,1061.888062,PLA,Vertical,24.249556108700617,0.7778143464128844
901,Speci1Force,0.5325918794,1066.526733,PLA,Vertical,24.35548602420644,0.7797831323572474
905,Speci1Force,0.5360479951,1071.839233,PLA,Vertical,24.4768036766385,0.7848433310395315
909,Speci1Force,0.5391741395,1077.446655,PLA,Vertical,24.6048562457182,0.7894204092240118
913,Speci1Force,0.5419556499,1082.411499,PLA,Vertical,24.718234733957527,0.793492898828697
917,Speci1Force,0.5452648997,1087.354858,PLA,Vertical,24.83112258506508,0.7983380669106883
921,Speci1Force,0.5489794612,1092.222046,PLA,Vertical,24.942270975108475,0.8037766635431918
925,Speci1Force,0.5512387156,1097.401733,PLA,Vertical,25.0605556748116,0.8070845030746707
929,Speci1Force,0.554233253,1102.321655,PLA,Vertical,25.17290831240009,0.8114688916544657
933,Speci1Force,0.5574948192,1107.37439,PLA,Vertical,25.288293902717516,0.8162442448023426
937,Speci1Force,0.5595585704,1112.382202,PLA,Vertical,25.40265361954784,0.8192658424597364
941,Speci1Force,0.5632817149,1117.253296,PLA,Vertical,25.513891208038366,0.8247170057101025
945,Speci1Force,0.5647093654,1121.921265,PLA,Vertical,25.620490180406485,0.8268072699853588
949,Speci1Force,0.5673958659,1126.58728,PLA,Vertical,25.727044530714775,0.8307406528550512
953,Speci1Force,0.5703312755,1131.848999,PLA,Vertical,25.847202534825303,0.8350384707174231
957,Speci1Force,0.5730044246,1137.534546,PLA,Vertical,25.977039187029003,0.8389523054172768
961,Speci1Force,0.5761572719,1142.71228,PLA,Vertical,26.095279287508564,0.8435684800878477
965,Speci1Force,0.5783330798,1147.833374,PLA,Vertical,26.21222594199589,0.8467541431918011
969,Speci1Force,0.5811263919,1152.710327,PLA,Vertical,26.323597328157113,0.8508439120058566
973,Speci1Force,0.5847465396,1158.317749,PLA,Vertical,26.451649897236813,0.856144274670571
977,Speci1Force,0.5873863101,1163.53064,PLA,Vertical,26.570692852249373,0.8600092387994144
981,Speci1Force,0.5903865695,1168.71814,PLA,Vertical,26.689155971683032,0.8644020051244511
985,Speci1Force,0.5939409137,1173.977905,PLA,Vertical,26.80926935373373,0.8696060229868229
989,Speci1Force,0.5958897471,1179.003296,PLA,Vertical,26.924030509248688,0.8724593661786237
993,Speci1Force,0.5985667109,1183.460327,PLA,Vertical,27.025812445763872,0.876378786090776
997,Speci1Force,0.6014658809,1188.370483,PLA,Vertical,27.137942064398263,0.8806235445095169
1001,Speci1Force,0.60443753,1193.989624,PLA,Vertical,27.266262251655633,0.8849744216691069
1005,Speci1Force,0.6065022349,1198.417358,PLA,Vertical,27.36737515414478,0.8879974156661786
1009,Speci1Force,0.6101509929,1204.210327,PLA,Vertical,27.499664923498518,0.8933396674963398
1013,Speci1Force,0.6118113399,1209.534546,PLA,Vertical,27.621250194108246,0.8957706294289899
1017,Speci1Force,0.6142680049,1214.370483,PLA,Vertical,27.731684928065768,0.8993675035139093
1021,Speci1Force,0.6166369319,1219.397827,PLA,Vertical,27.846490682804294,0.9028359178623719
1025,Speci1Force,0.6191241145,1223.862671,PLA,Vertical,27.948451039050013,0.906477473645681
1029,Speci1Force,0.6207434535,1228.575562,PLA,Vertical,28.056075862068965,0.9088483945827234
1033,Speci1Force,0.6231190562,1233.454468,PLA,Vertical,28.167491847453753,0.9123265830161055
1037,Speci1Force,0.6260372996,1238.380249,PLA,Vertical,28.27997828271295,0.9165992673499268
1041,Speci1Force,0.6285292506,1243.733765,PLA,Vertical,28.40223258734871,0.9202478046852123
1045,Speci1Force,0.6321436763,1248.470093,PLA,Vertical,28.51039262388673,0.9255397896046853
1049,Speci1Force,0.6343008876,1253.327515,PLA,Vertical,28.62131799497602,0.9286982248901904
1053,Speci1Force,0.6363474727,1257.847046,PLA,Vertical,28.72452719799041,0.9316946891654467
1057,Speci1Force,0.6394507289,1262.608765,PLA,Vertical,28.83326707010733,0.9362382560761348
1061,Speci1Force,0.6429125667,1267.55603,PLA,Vertical,28.946244119662023,0.9413068326500731
1065,Speci1Force,0.644448936,1272.194702,PLA,Vertical,29.052174058004113,0.9435562752562225
1069,Speci1Force,0.647988975,1277.341187,PLA,Vertical,29.169700548070335,0.9487393484626646
1073,Speci1Force,0.6510588527,1282.034546,PLA,Vertical,29.276879333181093,0.9532340449487555
1077,Speci1Force,0.6533700824,1287.345093,PLA,Vertical,29.398152386389587,0.9566179830161056
1081,Speci1Force,0.6559728384,1291.635132,PLA,Vertical,29.496120849509023,0.960428753147877
1085,Speci1Force,0.6592897177,1297.068726,PLA,Vertical,29.62020383649235,0.9652850918008784
1089,Speci1Force,0.6629060507,1302.625366,PLA,Vertical,29.74709673441425,0.9705798692532942
1093,Speci1Force,0.6651214361,1308.168335,PLA,Vertical,29.873677437771182,0.9738234789165446
1097,Speci1Force,0.6681865454,1313.045288,PLA,Vertical,29.985048823932406,0.9783111938506589
1101,Speci1Force,0.6714509726,1318.057007,PLA,Vertical,30.099497762046134,0.9830907358711567
1105,Speci1Force,0.6732116938,1322.586304,PLA,Vertical,30.202929984014613,0.9856686585651537
1109,Speci1Force,0.6767116785,1327.853882,PLA,Vertical,30.323221785795848,0.9907930871156663
1113,Speci1Force,0.6804023981,1333.646851,PLA,Vertical,30.455511555149577,0.9961967761346999
1117,Speci1Force,0.6834350824,1338.555054,PLA,Vertical,30.5675965745604,1.0006370166910687
1121,Speci1Force,0.6852651834,1343.701538,PLA,Vertical,30.685123041790366,1.003316520351391
1125,Speci1Force,0.6891065836,1348.93396,PLA,Vertical,30.80461201187486,1.008940825183016
1129,Speci1Force,0.6917454004,1353.723022,PLA,Vertical,30.91397629595798,1.0128043929721815
1133,Speci1Force,0.6944137812,1359.242554,PLA,Vertical,31.040021785795844,1.0167112462664714
1137,Speci1Force,0.6976143122,1364.299194,PLA,Vertical,31.155496551724138,1.0213972360175696
1141,Speci1Force,0.700753808,1369.193726,PLA,Vertical,31.267269376569992,1.0259938623718887
1145,Speci1Force,0.7027651072,1374.236694,PLA,Vertical,31.382431925097052,1.0289386635431919
1149,Speci1Force,0.7055927515,1379.650757,PLA,Vertical,31.506068897008454,1.0330786991215228
1153,Speci1Force,0.7094112635,1384.908569,PLA,Vertical,31.62613767983558,1.0386694926793556
1157,Speci1Force,0.7112165689,1389.810913,PLA,Vertical,31.738088901575704,1.0413126923865301
1161,Speci1Force,0.7147318125,1395.15271,PLA,Vertical,31.8600755880338,1.04645946193265
1165,Speci1Force,0.718126893,1400.320679,PLA,Vertical,31.978092692395524,1.0514302972181553
1169,Speci1Force,0.7201524973,1404.961304,PLA,Vertical,32.08406722996118,1.0543960428989751
1173,Speci1Force,0.722736001,1409.890991,PLA,Vertical,32.196642863667506,1.058178625183016
1177,Speci1Force,0.7258392572,1414.734741,PLA,Vertical,32.30725601735556,1.0627221920937042
1181,Speci1Force,0.7295280695,1419.980835,PLA,Vertical,32.42705720484129,1.068123088579795
1185,Speci1Force,0.7316795588,1424.723022,PLA,Vertical,32.535351039050006,1.0712731461200586
1189,Speci1Force,0.7347656488,1429.666382,PLA,Vertical,32.64823891299384,1.0757915795021962
1193,Speci1Force,0.738191247,1434.756226,PLA,Vertical,32.76447193423156,1.0808070966325038
1197,Speci1Force,0.7407470942,1439.420288,PLA,Vertical,32.87098168531628,1.0845491862371888
1201,Speci1Force,0.7435985804,1444.674194,PLA,Vertical,32.99096126969628,1.0887241294289898
1205,Speci1Force,0.7460294962,1449.601929,PLA,Vertical,33.103492327015296,1.0922833033674963
1209,Speci1Force,0.749168992,1454.525757,PLA,Vertical,33.215934163050925,1.0968799297218157
1213,Speci1Force,0.7521559,1459.299194,PLA,Vertical,33.32494163050925,1.1012531478770131
1217,Speci1Force,0.7546364069,1464.521851,PLA,Vertical,33.444207604475906,1.1048849295754026
1221,Speci1Force,0.7579532862,1469.844116,PLA,Vertical,33.5657482530258,1.109741268228404
1225,Speci1Force,0.7612015009,1474.49646,PLA,Vertical,33.671990408769126,1.1144970730600294
1229,Speci1Force,0.7628268003,1479.232788,PLA,Vertical,33.78015044530715,1.1168767207906298
1233,Speci1Force,0.7662371397,1484.269897,PLA,Vertical,33.895179196163504,1.1218698970717422
1237,Speci1Force,0.7697581053,1489.383179,PLA,Vertical,34.01194745375656,1.127025044363104
1241,Speci1Force,0.7718123198,1494.416382,PLA,Vertical,34.126887006165795,1.1300326790629576
1245,Speci1Force,0.7749499083,1499.129272,PLA,Vertical,34.23451180634848,1.1346265128843338
1249,Speci1Force,0.7776077986,1503.740601,PLA,Vertical,34.339817332724365,1.1385180067349925
1253,Speci1Force,0.7811611891,1509.129272,PLA,Vertical,34.462874446220596,1.1437206282576866
1257,Speci1Force,0.7846421003,1514.053101,PLA,Vertical,34.575316305092485,1.1488171307467059
1261,Speci1Force,0.787843585,1519.617554,PLA,Vertical,34.702387622744915,1.1535045168374816
1265,Speci1Force,0.7901090384,1524.510986,PLA,Vertical,34.81413532770039,1.1568214325036603
1269,Speci1Force,0.7933124304,1529.925049,PLA,Vertical,34.93777229961178,1.1615116111273793
1273,Speci1Force,0.7960418463,1534.829346,PLA,Vertical,35.04976812057547,1.165507827672035
1277,Speci1Force,0.7998412848,1540.110596,PLA,Vertical,35.17037213975794,1.171070695168375
1281,Speci1Force,0.8021987677,1545.354736,PLA,Vertical,35.29012870518383,1.1745223538799414
1285,Speci1Force,0.8048804998,1550.124268,PLA,Vertical,35.399046997031284,1.1784487551976575
1289,Speci1Force,0.8081992865,1554.829346,PLA,Vertical,35.506493400319705,1.1833078865300146
1293,Speci1Force,0.8107017279,1560.147705,PLA,Vertical,35.62794485042247,1.1869717831625182
1297,Speci1Force,0.8133615255,1564.718018,PLA,Vertical,35.73231372459466,1.19086606954612
1301,Speci1Force,0.8171666861,1570.120361,PLA,Vertical,35.85568305549212,1.1964373149341143
1305,Speci1Force,0.819939971,1574.784424,PLA,Vertical,35.962192829413105,1.2004977613469987
1309,Speci1Force,0.8235429525,1579.952393,PLA,Vertical,36.08020993377484,1.2057729904831627
1313,Speci1Force,0.8263715506,1584.177002,PLA,Vertical,36.17668422014158,1.2099144225475842
1317,Speci1Force,0.8289216757,1589.249268,PLA,Vertical,36.29251582553094,1.213648134260615
1321,Speci1Force,0.832121253,1594.811768,PLA,Vertical,36.41954254395981,1.218332727672035
1325,Speci1Force,0.8353761435,1599.796143,PLA,Vertical,36.53336704727107,1.2230983067349928
1329,Speci1Force,0.8387788534,1605.014893,PLA,Vertical,36.65254379995433,1.2280803124450952
1333,Speci1Force,0.8412688971,1610.198486,PLA,Vertical,36.77091769810459,1.2317260572474378
1337,Speci1Force,0.8430472612,1614.864502,PLA,Vertical,36.877472071249144,1.234329811420205
1341,Speci1Force,0.8469306231,1620.462158,PLA,Vertical,37.00530162137475,1.2400155535871158
1345,Speci1Force,0.8502341509,1625.585205,PLA,Vertical,37.12229287508564,1.2448523439238655
1349,Speci1Force,0.8537198305,1630.620361,PLA,Vertical,37.23727702671843,1.2499558279648608
1353,Speci1Force,0.8554650545,1635.036377,PLA,Vertical,37.33812233386618,1.252511060761347
1357,Speci1Force,0.8591405153,1640.522705,PLA,Vertical,37.46340956839461,1.257892408931186
1361,Speci1Force,0.8623934984,1645.669189,PLA,Vertical,37.580936035624575,1.2626551953147878
1365,Speci1Force,0.8658419847,1650.710205,PLA,Vertical,37.69605400776433,1.2677042235724743
1369,Speci1Force,0.8693000078,1655.966064,PLA,Vertical,37.81607819136789,1.2727672149341143
1373,Speci1Force,0.8727036715,1661.116455,PLA,Vertical,37.933693879881254,1.2777506171303075
1377,Speci1Force,0.8755007982,1666.114502,PLA,Vertical,38.04783060059374,1.281845971010249
1381,Speci1Force,0.8782178164,1671.634033,PLA,Vertical,38.173876067595344,1.285824035724744
1385,Speci1Force,0.8819428682,1677.247314,PLA,Vertical,38.30206243434574,1.2912779915080528
1389,Speci1Force,0.885650754,1682.516846,PLA,Vertical,38.4223988581868,1.296706814055637
1393,Speci1Force,0.8884106874,1687.323486,PLA,Vertical,38.53216455811829,1.3007477121522695
1397,Speci1Force,0.8908835649,1692.219971,PLA,Vertical,38.64398198218772,1.3043683234260615
1401,Speci1Force,0.8934713602,1697.477783,PLA,Vertical,38.764050765014844,1.3081571891654467
1405,Speci1Force,0.8973451853,1702.643799,PLA,Vertical,38.882023270153006,1.3138289682284041
1409,Speci1Force,0.9009557962,1708.030518,PLA,Vertical,39.00503580726193,1.3191153677891654
1413,Speci1Force,0.9046236277,1713.657471,PLA,Vertical,39.13353439141356,1.32448554568082
1417,Speci1Force,0.908362031,1718.964111,PLA,Vertical,39.254718223338664,1.3299590497803806
1421,Speci1Force,0.9111925364,1723.575439,PLA,Vertical,39.36002372687828,1.3341032743777452
1425,Speci1Force,0.9150778055,1728.709229,PLA,Vertical,39.47726031057319,1.339791808931186
1429,Speci1Force,0.9176784754,1733.580322,PLA,Vertical,39.58849787622745,1.3435995247437775
1433,Speci1Force,0.919626832,1738.133057,PLA,Vertical,39.692465334551265,1.3464521698389458
1437,Speci1Force,0.9233404398,1743.453369,PLA,Vertical,39.8139613838776,1.3518893701317716
1441,Speci1Force,0.9270750284,1748.738525,PLA,Vertical,39.93465460150719,1.3573572890190337
1445,Speci1Force,0.9304529428,1753.756104,PLA,Vertical,40.04923736012788,1.3623029909224011
1449,Speci1Force,0.9340213537,1758.738892,PLA,Vertical,40.163025622288195,1.3675276042459736
1453,Speci1Force,0.9373649359,1764.190063,PLA,Vertical,40.287510002283625,1.3724230393850658
1457,Speci1Force,0.9396823645,1769.428345,PLA,Vertical,40.40713279287509,1.3758160534407027
1461,Speci1Force,0.9420436621,1773.947876,PLA,Vertical,40.51034199588947,1.3792732973645683
1465,Speci1Force,0.9454120398,1779.029907,PLA,Vertical,40.62639659739667,1.3842050363103953
1469,Speci1Force,0.9491542578,1784.244751,PLA,Vertical,40.745484151632795,1.3896841256222547
1473,Speci1Force,0.9525302649,1789.307251,PLA,Vertical,40.86109273806805,1.3946270349926795
1477,Speci1Force,0.9565757513,1794.38147,PLA,Vertical,40.976968942680976,1.4005501483162521
1481,Speci1Force,0.9598602057,1799.840454,PLA,Vertical,41.101631742406944,1.405359012737921
1485,Speci1Force,0.9634603262,1805.130493,PLA,Vertical,41.22243646951359,1.4106300530014642
1489,Speci1Force,0.9670060873,1809.694946,PLA,Vertical,41.32667152317881,1.4158215040995608
1493,Speci1Force,0.9692281485,1815.224243,PLA,Vertical,41.4529400091345,1.4190748879941437
1497,Speci1Force,0.9725221395,1820.495728,PLA,Vertical,41.57332103219913,1.42389771522694
1501,Speci1Force,0.97623384,1825.692993,PLA,Vertical,41.69200714775063,1.429332122986823
1505,Speci1Force,0.9799989462,1830.823853,PLA,Vertical,41.809176821192054,1.4348447235724746
1509,Speci1Force,0.9836992025,1836.286743,PLA,Vertical,41.93392881936515,1.4402623755490485
1513,Speci1Force,0.9869121313,1841.433228,PLA,Vertical,42.05145530943138,1.4449665172767203
1517,Speci1Force,0.9902995825,1846.396118,PLA,Vertical,42.16478917561087,1.4499261822840412
1521,Speci1Force,0.9927905798,1850.808228,PLA,Vertical,42.26554528431149,1.4535733232796486
1525,Speci1Force,0.9954875708,1855.196899,PLA,Vertical,42.36576613382051,1.4575220655929724
1529,Speci1Force,0.9994243383,1860.411743,PLA,Vertical,42.48485368805663,1.4632860004392387
1533,Speci1Force,1.00126493,1865.337524,PLA,Vertical,42.597340123315824,1.4659808638360177
1537,Speci1Force,1.00501287,1870.556274,PLA,Vertical,42.71651687599909,1.4714683308931187
1541,Speci1Force,1.008256316,1875.427368,PLA,Vertical,42.82775446448961,1.4762171537335287
1545,Speci1Force,1.011868834,1881.153931,PLA,Vertical,42.958527768897014,1.4815063455344069
1549,Speci1Force,1.015725493,1886.579712,PLA,Vertical,43.08243233614981,1.4871529912152268
1553,Speci1Force,1.01954782,1891.855103,PLA,Vertical,43.20290255766157,1.4927493704245975
1557,Speci1Force,1.022889495,1896.718384,PLA,Vertical,43.31396172642156,1.4976420131771597
1561,Speci1Force,1.02676332,1901.821899,PLA,Vertical,43.430506942224255,1.5033137920937043
1565,Speci1Force,1.030507445,1907.142212,PLA,Vertical,43.55200301438685,1.508795673499268
1569,Speci1Force,1.034190536,1912.407837,PLA,Vertical,43.672250216944505,1.5141881932650074
1573,Speci1Force,1.037935615,1917.806274,PLA,Vertical,43.79553034939484,1.5196714714494879
1577,Speci1Force,1.041541457,1923.335571,PLA,Vertical,43.921798835350536,1.5249508887262078
1581,Speci1Force,1.045085311,1928.718384,PLA,Vertical,44.044722174012335,1.5301395475841875
1585,Speci1Force,1.04874742,1934.208618,PLA,Vertical,44.17009860698789,1.535501346998536
1589,Speci1Force,1.05247438,1939.716431,PLA,Vertical,44.2958764786481,1.5409580966325038
1593,Speci1Force,1.056321502,1944.642212,PLA,Vertical,44.40836291390728,1.5465907789165447
1597,Speci1Force,1.059647918,1949.610962,PLA,Vertical,44.521830600593745,1.5514610805270865
1601,Speci1Force,1.063351989,1954.622681,PLA,Vertical,44.63627953870747,1.556884317715959
1605,Speci1Force,1.067109466,1959.968384,PLA,Vertical,44.7583554236127,1.562385748169839
1609,Speci1Force,1.070880294,1965.357056,PLA,Vertical,44.8814125599452,1.567906726207906
1613,Speci1Force,1.074169517,1970.339478,PLA,Vertical,44.99519246403289,1.572722572474378
1617,Speci1Force,1.07810533,1975.587524,PLA,Vertical,45.11503822790591,1.5784851098096635
1621,Speci1Force,1.081439376,1980.50354,PLA,Vertical,45.22730166704727,1.5833665827232797
1625,Speci1Force,1.085175157,1985.723999,PLA,Vertical,45.346517446905686,1.5888362474377744
1629,Speci1Force,1.088471055,1990.579468,PLA,Vertical,45.45739821877141,1.5936618667642752
1633,Speci1Force,1.091940522,1995.31189,PLA,Vertical,45.5654690568623,1.5987416134699857
1637,Speci1Force,1.095341325,2000.40564,PLA,Vertical,45.68179127654716,1.6037208272327963
1641,Speci1Force,1.098953843,2005.577515,PLA,Vertical,45.79989757935602,1.6090100190336754
1645,Speci1Force,1.101563096,2010.018921,PLA,Vertical,45.90132269924641,1.6128303016105419
1649,Speci1Force,1.104864717,2014.634155,PLA,Vertical,46.00671740123316,1.6176643001464133
1653,Speci1Force,1.108597398,2019.657593,PLA,Vertical,46.121433957524545,1.6231294260614932
1657,Speci1Force,1.112429261,2024.619507,PLA,Vertical,46.23474553551039,1.6287397672035138
1661,Speci1Force,1.115831971,2029.59021,PLA,Vertical,46.34825782142042,1.6337217730600293
1665,Speci1Force,1.119772553,2034.572632,PLA,Vertical,46.46203772550811,1.6394912928257688
1669,Speci1Force,1.123037934,2039.320679,PLA,Vertical,46.570465380223794,1.6442722313323574
1673,Speci1Force,1.127390504,2044.127319,PLA,Vertical,46.68023108015529,1.650644954612006
1677,Speci1Force,1.13052237,2049.088379,PLA,Vertical,46.79352315597168,1.6552304099560762
1681,Speci1Force,1.133921266,2054.227051,PLA,Vertical,46.91087122630737,1.6602068316251832
1685,Speci1Force,1.138676286,2058.83252,PLA,Vertical,47.0160429321763,1.6671687935578332
1689,Speci1Force,1.141400933,2063.682129,PLA,Vertical,47.126789883535054,1.671158027818448
1693,Speci1Force,1.145925164,2068.814941,PLA,Vertical,47.24400413336379,1.6777820849194731
1697,Speci1Force,1.150146127,2073.855957,PLA,Vertical,47.359122105503545,1.6839621185944362
1701,Speci1Force,1.153951287,2078.789551,PLA,Vertical,47.47178696049326,1.689533363103953
1705,Speci1Force,1.157333016,2084.04541,PLA,Vertical,47.59181114409683,1.6944846500732063
1709,Speci1Force,1.16116488,2089.111816,PLA,Vertical,47.70750892897922,1.700094992679356
1713,Speci1Force,1.164176583,2093.850098,PLA,Vertical,47.81571358757707,1.7045045139092239
1717,Speci1Force,1.168550134,2099.259277,PLA,Vertical,47.939239027175155,1.7109079560761347
1721,Speci1Force,1.173299432,2103.915527,PLA,Vertical,48.045570381365614,1.7178615402635433
1725,Speci1Force,1.17729342,2108.64209,PLA,Vertical,48.15350742178579,1.7237092532942901
1729,Speci1Force,1.181075692,2113.76123,PLA,Vertical,48.27040945421329,1.7292469868228406
1733,Speci1Force,1.186559319,2118.513184,PLA,Vertical,48.37892633021237,1.7372757232796485
[...]
32724,Speci21Force,1.288069963,1087.669189,PETG,Horizontal,25.318184101489756,1.9737510925528654
32728,Speci21Force,1.296423197,1092.012207,PETG,Horizontal,25.419278561452515,1.9865510220655838
32732,Speci21Force,1.305189371,1096.189697,PETG,Horizontal,25.516519948789572,1.999983712840944
32736,Speci21Force,1.312864542,1100.384033,PETG,Horizontal,25.614153468342646,2.0117446245786086
32740,Speci21Force,1.32243371,1104.873291,PETG,Horizontal,25.718652025139665,2.0264077689243027
32744,Speci21Force,1.330986261,1109.206787,PETG,Horizontal,25.81952483705773,2.0395131182960466
32748,Speci21Force,1.341258287,1113.650146,PETG,Horizontal,25.922954981378023,2.055253274593932
32752,Speci21Force,1.350285769,1118.004883,PETG,Horizontal,26.02432222998138,2.0690863760343245
32756,Speci21Force,1.359290361,1122.379883,PETG,Horizontal,26.126161149906892,2.0828844023904383
32760,Speci21Force,1.368676424,1126.749878,PETG,Horizontal,26.22788356610801,2.0972669690468893
32764,Speci21Force,1.376675844,1131.186401,PETG,Horizontal,26.33115458566108,2.109524737971192
32768,Speci21Force,1.387513399,1135.536011,PETG,Horizontal,26.43240249068901,2.1261314725712532
32772,Speci21Force,1.395631075,1140.117065,PETG,Horizontal,26.53903782588454,2.1385704489733373
32776,Speci21Force,1.405017138,1144.504761,PETG,Horizontal,26.64117227653631,2.1529530156297887
32780,Speci21Force,1.415557146,1148.766479,PETG,Horizontal,26.74037427839851,2.169103809377873
32784,Speci21Force,1.425107241,1153.026245,PETG,Horizontal,26.83953084264432,2.183737727551333
32788,Speci21Force,1.435093164,1157.534058,PETG,Horizontal,26.94446131284916,2.1990394790070487
32792,Speci21Force,1.445617914,1161.956421,PETG,Horizontal,27.047402723463687,2.2151668924302785
32796,Speci21Force,1.454764962,1166.222412,PETG,Horizontal,27.146704189944135,2.2291832087036467
32800,Speci21Force,1.465121865,1170.85376,PETG,Horizontal,27.254510242085658,2.2450534247624883
32804,Speci21Force,1.476939797,1175.317261,PETG,Horizontal,27.35840924115456,2.2631624226172233
32808,Speci21Force,1.487325311,1179.913696,PETG,Horizontal,27.465402607076353,2.279076480232914
32812,Speci21Force,1.496701837,1184.121216,PETG,Horizontal,27.563343016759777,2.2934444330370822
32816,Speci21Force,1.50913775,1188.360229,PETG,Horizontal,27.66201650372439,2.3125003830830524
32820,Speci21Force,1.520427346,1192.646118,PETG,Horizontal,27.761781145251394,2.3297997946674838
32824,Speci21Force,1.531621575,1196.956421,PETG,Horizontal,27.862114082867784,2.3469530723260803
32828,Speci21Force,1.543334603,1201.354736,PETG,Horizontal,27.964495716945997,2.3649013224026967
32832,Speci21Force,1.553833604,1205.660889,PETG,Horizontal,28.064732053072625,2.3809892798038614
32836,Speci21Force,1.565749764,1210.137573,PETG,Horizontal,28.168937918994413,2.399248795586883
32840,Speci21Force,1.575962663,1214.597534,PETG,Horizontal,28.272754515828677,2.41489834967821
32844,Speci21Force,1.585386872,1219.199585,PETG,Horizontal,28.37987860800745,2.4293393686791296
32848,Speci21Force,1.593184114,1223.625366,PETG,Horizontal,28.482899581005586,2.4412873337419554
32852,Speci21Force,1.60214293,1228.044312,PETG,Horizontal,28.585761452513967,2.4550152160588414
32856,Speci21Force,1.611237168,1232.339233,PETG,Horizontal,28.685736336126627,2.468950609868219
32860,Speci21Force,1.621819139,1236.832031,PETG,Horizontal,28.790317295158285,2.4851657048728164
32864,Speci21Force,1.636122346,1241.119385,PETG,Horizontal,28.890116038175044,2.5070829696598222
32868,Speci21Force,1.649143815,1245.60144,PETG,Horizontal,28.994446927374298,2.52703618602513
32872,Speci21Force,1.662768006,1249.825317,PETG,Horizontal,29.09276808659218,2.5479129727244865
32876,Speci21Force,1.675529718,1254.337402,PETG,Horizontal,29.197797998137805,2.567468155072019
32880,Speci21Force,1.689419031,1258.709961,PETG,Horizontal,29.299580097765364,2.5887511967514554
32884,Speci21Force,1.700734377,1262.904297,PETG,Horizontal,29.397213617318435,2.6060900658902852
32888,Speci21Force,1.716370821,1267.234863,PETG,Horizontal,29.49801822625698,2.6300502926754517
32892,Speci21Force,1.731948137,1271.516602,PETG,Horizontal,29.597686266294225,2.6539199157217284
32896,Speci21Force,1.74611783,1275.669678,PETG,Horizontal,29.6943593575419,2.6756325927060987
32900,Speci21Force,1.759774446,1279.956055,PETG,Horizontal,29.794135358473,2.696559065277352
32904,Speci21Force,1.777119875,1284.036743,PETG,Horizontal,29.88912344040968,2.7231380248237813
32908,Speci21Force,1.792313814,1288.268921,PETG,Horizontal,29.987637825884544,2.7464201869445293
32912,Speci21Force,1.809512377,1292.692383,PETG,Horizontal,30.090604818435754,2.7727740989886605
32916,Speci21Force,1.825289965,1296.891968,PETG,Horizontal,30.188360521415266,2.7969506052712227
32920,Speci21Force,1.840983629,1301.250732,PETG,Horizontal,30.289821508379887,2.8209985121054237
32924,Speci21Force,1.858689547,1305.244995,PETG,Horizontal,30.38279783519553,2.8481298605577687
32928,Speci21Force,1.875712633,1309.30188,PETG,Horizontal,30.477231843575417,2.8742148835427517
32932,Speci21Force,1.894379854,1313.415039,PETG,Horizontal,30.572975768156425,2.902819267545204
32936,Speci21Force,1.911786199,1317.34082,PETG,Horizontal,30.664358007448786,2.929491570640515
32940,Speci21Force,1.930737615,1320.952759,PETG,Horizontal,30.74843479981378,2.95853143579528
32944,Speci21Force,1.949067235,1324.885986,PETG,Horizontal,30.83999036312849,2.9866185029114307
32948,Speci21Force,1.967414021,1328.547363,PETG,Horizontal,30.925217946927372,3.014731874042292
32952,Speci21Force,1.987206578,1332.028076,PETG,Horizontal,31.006240130353817,3.0450606466441923
32956,Speci21Force,2.005065203,1336.085327,PETG,Horizontal,31.10068265828678,3.072425992951272
32960,Speci21Force,2.025748491,1339.803223,PETG,Horizontal,31.187225861266292,3.104119661354581
32964,Speci21Force,2.047383547,1343.448975,PETG,Horizontal,31.27208973463687,3.137271754520379
32968,Speci21Force,2.068488359,1346.644653,PETG,Horizontal,31.346477025139666,3.1696113377260184
32972,Speci21Force,2.090491533,1349.644653,PETG,Horizontal,31.4163094273743,3.2033275099601592
32976,Speci21Force,2.112183809,1352.929443,PETG,Horizontal,31.49277101955307,3.236567283174992
32980,Speci21Force,2.134089708,1356.07959,PETG,Horizontal,31.56609846368715,3.2701343977934414
32984,Speci21Force,2.157025576,1358.55896,PETG,Horizontal,31.623811918063314,3.305279767085504
32988,Speci21Force,2.179541349,1361.343384,PETG,Horizontal,31.68862625698324,3.3397814112779645
32992,Speci21Force,2.202858686,1364.009277,PETG,Horizontal,31.75068149441341,3.3755113178056995
32996,Speci21Force,2.226277113,1367.086304,PETG,Horizontal,31.822306890130353,3.4113961277965057
33000,Speci21Force,2.25088954,1369.014893,PETG,Horizontal,31.86719955772812,3.449110542445602
33004,Speci21Force,2.274336576,1371.423218,PETG,Horizontal,31.923259264432026,3.4850391909285934
33008,Speci21Force,2.299488783,1373.264038,PETG,Horizontal,31.96610889199255,3.5235807278577993
33012,Speci21Force,2.324724913,1375.41687,PETG,Horizontal,32.01622136871509,3.5622508627030336
33016,Speci21Force,2.349486113,1377.756104,PETG,Horizontal,32.070672811918065,3.600193247011952
33020,Speci21Force,2.374411345,1379.437988,PETG,Horizontal,32.10982281191806,3.6383869828378788
33024,Speci21Force,2.398993254,1381.093506,PETG,Horizontal,32.14835907821229,3.676054633772602
33028,Speci21Force,2.425558805,1382.265015,PETG,Horizontal,32.175628840782124,3.716761883236285
33032,Speci21Force,2.452133894,1383.677002,PETG,Horizontal,32.208496322160144,3.757483748084585
33036,Speci21Force,2.476849318,1384.92749,PETG,Horizontal,32.23760451582868,3.795355988354275
33040,Speci21Force,2.503312349,1386.198975,PETG,Horizontal,32.267201466480444,3.8359061431198285
33044,Speci21Force,2.531129122,1385.796265,PETG,Horizontal,32.25782739757914,3.8785306803555004
33048,Speci21Force,2.558482409,1386.771118,PETG,Horizontal,32.280519506517685,3.920445003064664
33052,Speci21Force,2.585864305,1387.044678,PETG,Horizontal,32.28688729050279,3.9624031642660125
33056,Speci21Force,2.613801241,1387.113037,PETG,Horizontal,32.288478514897584,4.0052118311369895
33060,Speci21Force,2.641804934,1387.430664,PETG,Horizontal,32.295872067039106,4.048122791909286
33064,Speci21Force,2.670052767,1387.226318,PETG,Horizontal,32.29111540968343,4.091407856267239
33068,Speci21Force,2.697831392,1387.457642,PETG,Horizontal,32.29650004655494,4.133973938093778
33072,Speci21Force,2.727505922,1387.000488,PETG,Horizontal,32.28585865921787,4.179445176218204
33076,Speci21Force,2.756581545,1386.512573,PETG,Horizontal,32.27450123370577,4.22399868985596
33080,Speci21Force,2.786423922,1385.617798,PETG,Horizontal,32.25367313780261,4.269727125344774
33084,Speci21Force,2.815726519,1384.84314,PETG,Horizontal,32.23564106145251,4.314628438553478
33088,Speci21Force,2.845744848,1383.930054,PETG,Horizontal,32.214386731843575,4.360626490959239
33092,Speci21Force,2.875940084,1383.112427,PETG,Horizontal,32.19535444599627,4.406895623659208
33096,Speci21Force,2.906110525,1381.853149,PETG,Horizontal,32.1660416433892,4.45312676218204
33100,Speci21Force,2.937677145,1380.558838,PETG,Horizontal,32.13591336126629,4.501497310756972
33104,Speci21Force,2.968702078,1379.28418,PETG,Horizontal,32.10624255121043,4.549037814894269
33108,Speci21Force,2.999517202,1377.473877,PETG,Horizontal,32.0641032821229,4.596256821942997
33112,Speci21Force,3.027921438,1374.942505,PETG,Horizontal,32.00517935288641,4.639781547655531
33116,Speci21Force,3.059610128,1373.301392,PETG,Horizontal,31.966978398510243,4.688339148023291
33120,Speci21Force,3.092473745,1371.323975,PETG,Horizontal,31.920949138733704,4.738697126877107
33124,Speci21Force,3.124383688,1369.162964,PETG,Horizontal,31.870646275605218,4.787593760343242
33128,Speci21Force,3.15699935,1366.616699,PETG,Horizontal,31.811375675046552,4.83757178976402
33132,Speci21Force,3.188518286,1364.03418,PETG,Horizontal,31.75126117318436,4.885869270609867
33136,Speci21Force,3.220561743,1360.776001,PETG,Horizontal,31.675419017690874,4.93497049187864
33140,Speci21Force,3.249961853,1358.285034,PETG,Horizontal,31.61743561452514,4.980021227398099
33144,Speci21Force,3.281894684,1355.476196,PETG,Horizontal,31.552052979515828,5.028952932883849
33148,Speci21Force,3.316474915,1352.183228,PETG,Horizontal,31.47540102420857,5.081941334661354
33152,Speci21Force,3.350540161,1349.511353,PETG,Horizontal,31.413206540968343,5.134140608335887
33156,Speci21Force,3.382144928,1346.271851,PETG,Horizontal,31.337799138733704,5.182569610787619
33160,Speci21Force,3.414260864,1342.693481,PETG,Horizontal,31.254503747672253,5.23178189396261
33164,Speci21Force,3.448303223,1338.924927,PETG,Horizontal,31.166781354748604,5.283946097149862
33168,Speci21Force,3.481517792,1335.038574,PETG,Horizontal,31.076316899441338,5.334841851057308
33172,Speci21Force,3.511398315,1330.942871,PETG,Horizontal,30.98097930633147,5.380628738890591
33176,Speci21Force,3.544727325,1327.155762,PETG,Horizontal,30.892825000000002,5.43169985442844
33180,Speci21Force,3.575317383,1323.233765,PETG,Horizontal,30.80153084264432,5.478573985596077
33184,Speci21Force,3.604093552,1319.032715,PETG,Horizontal,30.703741038175046,5.522668636224333
33188,Speci21Force,3.632455826,1314.853516,PETG,Horizontal,30.60645986964618,5.5661290622126876
33192,Speci21Force,3.665205002,1311.055176,PETG,Horizontal,30.518044134078213,5.616311679436102
33196,Speci21Force,3.692923069,1306.845581,PETG,Horizontal,30.420055423649906,5.658784966288691
33200,Speci21Force,3.722469807,1302.445435,PETG,Horizontal,30.317631168528866,5.704060384615384
33204,Speci21Force,3.746914387,1298.389038,PETG,Horizontal,30.223208519553072,5.741517601900091
33208,Speci21Force,3.773918629,1294.106567,PETG,Horizontal,30.123523440409684,5.782897071713148
33212,Speci21Force,3.799652576,1289.77063,PETG,Horizontal,30.02259380819367,5.822330027581979
33216,Speci21Force,3.826233387,1285.445557,PETG,Horizontal,29.921917062383613,5.863060660435181
33220,Speci21Force,3.851639271,1281.221313,PETG,Horizontal,29.823587360335196,5.901990914802329
33224,Speci21Force,3.877827168,1276.692139,PETG,Horizontal,29.718159660148974,5.942119472877719
33228,Speci21Force,3.90192461,1272.217285,PETG,Horizontal,29.61399639199255,5.979044759423843
33232,Speci21Force,3.923267841,1267.966919,PETG,Horizontal,29.51505863594041,6.011749679742567
33236,Speci21Force,3.947620869,1263.560669,PETG,Horizontal,29.412492295158284,6.04906660894882
33240,Speci21Force,3.969566822,1259.193726,PETG,Horizontal,29.310840921787708,6.082695099601594
33244,Speci21Force,3.991623402,1254.674683,PETG,Horizontal,29.205649045623833,6.116493107569721
33248,Speci21Force,4.013210773,1250.112671,PETG,Horizontal,29.099456959962758,6.149572131474103
33252,Speci21Force,4.034756184,1245.703003,PETG,Horizontal,28.99681105679702,6.18258685871897
33256,Speci21Force,4.05521059,1241.590698,PETG,Horizontal,28.901087011173182,6.213929803861476
33260,Speci21Force,4.073532581,1237.145386,PETG,Horizontal,28.797611405959028,6.242005180815201
33264,Speci21Force,4.091450214,1232.72644,PETG,Horizontal,28.69474953445065,6.2694609469813045
33268,Speci21Force,4.108154774,1228.032104,PETG,Horizontal,28.585477281191803,6.295057882316886
33272,Speci21Force,4.125645161,1223.082397,PETG,Horizontal,28.470260637802603,6.321858965675757
33276,Speci21Force,4.140530109,1218.358765,PETG,Horizontal,28.36030644785847,6.344667650934722
33280,Speci21Force,4.158334732,1213.684814,PETG,Horizontal,28.25150870577281,6.371950248237818
33284,Speci21Force,4.177358627,1209.088623,PETG,Horizontal,28.144521019553075,6.401101175298805
33288,Speci21Force,4.199666977,1204.4729,PETG,Horizontal,28.03707867783985,6.435284978547348
33292,Speci21Force,4.217912674,1200.269775,PETG,Horizontal,27.939240572625696,6.463243447747471
33296,Speci21Force,4.239938736,1195.829346,PETG,Horizontal,27.835878631284917,6.496994692001225
33300,Speci21Force,4.261064529,1191.597412,PETG,Horizontal,27.737369925512105,6.529366425068956
33304,Speci21Force,4.28606987,1187.227905,PETG,Horizontal,27.635658868715083,6.5676829144958635
33308,Speci21Force,4.308446884,1182.746948,PETG,Horizontal,27.531353538175047,6.601971933803248
33312,Speci21Force,4.330053329,1178.365112,PETG,Horizontal,27.42935549348231,6.635080185412197
33316,Speci21Force,4.350393295,1174.056519,PETG,Horizontal,27.329062360335193,6.666247770456635
33320,Speci21Force,4.372014999,1169.646362,PETG,Horizontal,27.226405074487893,6.69937940392277
33324,Speci21Force,4.396001816,1165.270874,PETG,Horizontal,27.124554795158286,6.736135176218204
33328,Speci21Force,4.421476364,1160.882446,PETG,Horizontal,27.022403305400374,6.7751706466441926
33332,Speci21Force,4.443254471,1156.712036,PETG,Horizontal,26.925326722532585,6.80854194146491
33336,Speci21Force,4.465673447,1152.203735,PETG,Horizontal,26.820384892923652,6.842895260496476
33340,Speci21Force,4.489889145,1147.78894,PETG,Horizontal,26.71761964618249,6.88000175452038
33344,Speci21Force,4.516691208,1143.092407,PETG,Horizontal,26.608296252327747,6.921071418939626
33348,Speci21Force,4.534917831,1138.668579,PETG,Horizontal,26.50532074022346,6.949000660435181
33352,Speci21Force,4.555692673,1134.355713,PETG,Horizontal,26.404928142458097,6.980834619981612
33356,Speci21Force,4.577356339,1130.016113,PETG,Horizontal,26.303913244878956,7.014030553171927
33360,Speci21Force,4.599245071,1125.538818,PETG,Horizontal,26.19969315642458,7.047571362243335
33364,Speci21Force,4.624292374,1120.938965,PETG,Horizontal,26.09262022811918,7.085952151394423
33368,Speci21Force,4.648443222,1116.330322,PETG,Horizontal,25.985342690875232,7.122959273674533
33372,Speci21Force,4.669578075,1111.707886,PETG,Horizontal,25.877744087523276,7.155344889672081
33376,Speci21Force,4.693618298,1107.555542,PETG,Horizontal,25.781088035381753,7.1921824977015
33380,Speci21Force,4.719325542,1103.003784,PETG,Horizontal,25.67513463687151,7.2315745357033405
33384,Speci21Force,4.740935802,1098.524292,PETG,Horizontal,25.57086340782123,7.264688633159669
33388,Speci21Force,4.763072491,1094.111938,PETG,Horizontal,25.468154981378024,7.298609394728777
33392,Speci21Force,4.786742687,1089.733521,PETG,Horizontal,25.36623652234637,7.334879998467668
33396,Speci21Force,4.810569286,1085.239868,PETG,Horizontal,25.26163566108007,7.371390263561139
33400,Speci21Force,4.833953381,1080.931396,PETG,Horizontal,25.161345344506515,7.4072224655225245
33404,Speci21Force,4.858142376,1076.285889,PETG,Horizontal,25.05320970670391,7.444288041679435
33408,Speci21Force,4.881587505,1072.074463,PETG,Horizontal,24.955178375232773,7.480213768004902
33412,Speci21Force,4.905940533,1067.989258,PETG,Horizontal,24.86008514897579,7.517530697211154
33416,Speci21Force,4.930598736,1063.692383,PETG,Horizontal,24.760064781191808,7.55531525589948
33420,Speci21Force,4.948642254,1059.222656,PETG,Horizontal,24.656020856610798,7.582963919705792
33424,Speci21Force,4.970447063,1054.566772,PETG,Horizontal,24.54764366852886,7.616376130861171
33428,Speci21Force,4.993815899,1050.024292,PETG,Horizontal,24.441906238361266,7.65218495096537
33432,Speci21Force,5.021380901,1045.444702,PETG,Horizontal,24.335304981378027,7.694423691388291
33436,Speci21Force,5.047973156,1040.871826,PETG,Horizontal,24.22886000931099,7.735171860251302
33440,Speci21Force,5.071712017,1036.576172,PETG,Horizontal,24.128868063314712,7.771547681581367
33444,Speci21Force,5.097476482,1032.140381,PETG,Horizontal,24.025614082867783,7.811027401164572
33448,Speci21Force,5.122340679,1027.735107,PETG,Horizontal,23.923070460893854,7.849127611094084
33452,Speci21Force,5.150268078,1023.169128,PETG,Horizontal,23.816786033519552,7.891921664112779
33456,Speci21Force,5.176959515,1018.939514,PETG,Horizontal,23.718331331471138,7.932821812749004
33460,Speci21Force,5.201163769,1014.274475,PETG,Horizontal,23.60974103817505,7.9699107707631
33464,Speci21Force,5.230857372,1010.004395,PETG,Horizontal,23.510344390130353,8.01541123505976
33468,Speci21Force,5.255195141,1005.66687,PETG,Horizontal,23.409377793296088,8.052704782408824
33472,Speci21Force,5.279754162,1001.445679,PETG,Horizontal,23.31111915735568,8.090337361323934
33476,Speci21Force,5.305621624,997.1346436,PETG,Horizontal,23.21076917132216,8.129974906527734
33480,Speci21Force,5.328570843,992.5994873,PETG,Horizontal,23.105202218342644,8.165140733987126
33484,Speci21Force,5.351485729,988.2962646,PETG,Horizontal,23.00503409217877,8.200253951884768
33488,Speci21Force,5.36942625,983.5794678,PETG,Horizontal,22.89523900837989,8.227744790070487
33492,Speci21Force,5.38820219,979.0775146,PETG,Horizontal,22.790444939478583,8.256515767698437
33496,Speci21Force,5.402553082,974.8519287,PETG,Horizontal,22.692084001396648,8.278506101746858
33500,Speci21Force,5.419192791,970.2684326,PETG,Horizontal,22.58539182029795,8.304003663806313
33504,Speci21Force,5.435885906,965.3846436,PETG,Horizontal,22.471709581005587,8.329583061599754
33508,Speci21Force,5.451182842,960.9334717,PETG,Horizontal,22.36809757216015,8.353023049341097
33512,Speci21Force,5.463851452,955.9764404,PETG,Horizontal,22.252710437616386,8.37243556849525
33516,Speci21Force,5.476211071,951.1072998,PETG,Horizontal,22.139369175977652,8.391374610787619
33520,Speci21Force,5.484862804,945.9119873,PETG,Horizontal,22.018435458566106,8.404631939932576
33524,Speci21Force,5.494307995,939.6190186,PETG,Horizontal,21.871951084729982,8.419105110327918
33528,Speci21Force,5.499396801,935.1580811,PETG,Horizontal,21.76811175744879,8.426902851670242
33532,Speci21Force,5.504546642,929.7440186,PETG,Horizontal,21.64208609404097,8.434794118908979
33536,Speci21Force,5.509681225,923.5799561,PETG,Horizontal,21.498602330074487,8.44266200582286
33540,Speci21Force,5.515677929,915.6658936,PETG,Horizontal,21.314382998137802,8.451850948513636
33544,Speci21Force,5.522170544,905.3690186,PETG,Horizontal,21.074697825884545,8.461799791602818
33548,Speci21Force,5.528357983,890.9783936,PETG,Horizontal,20.73972052141527,8.471281003677596
33552,Speci21Force,5.53544569,869.2908936,PETG,Horizontal,20.234890446927373,8.482141725406068
33556,Speci21Force,5.543738842,828.0096436,PETG,Horizontal,19.273967495344507,8.494849589334967